Workbook

Sheet Raw Data
A1: Transaction ID | B1: Date | C1: Category | D1: Item | E1: Price Per Unit | F1: Quantity | G1: Total Spent | H1: Payment Method
A2: TXN_1557 | B2: 45755 | C2: Milk Products | D2: Milk_Cheese_200g | F2: 6 | G2: 660 | H2: Credit Card
A3: TXN_1251 | B3: 45808 | C3: Furniture | D3: Furn_Chair | E3: 2500 | F3: 2 | G3: 5000 | H3: Credit Card
A4: TXN_1150 | B4: 45860 | C4: Computers | E4: 800 | F4: 4 | G4: 3200 | H4: Cash
A5: TXN_1350 | B5: 45829 | C5: Milk Products | D5: Milk_Butter_500g | E5: 250 | F5: 6 | G5: 1500 | H5: Cash
A6: TXN_1406 | B6: 45878 | C6: Butchers | D6: Meat_Chicken_1kg | E6: 220 | F6: 6 | G6: 1320 | H6: Debit Card
A7: TXN_1494 | B7: 45866 | C7: Patisserie | D7: Pat_Cake_Slice | E7: 90 | F7: 2 | G7: 180 | H7: Debit Card
A8: TXN_1547 | B8: 45705 | C8: Butchers | E8: 190 | F8: 4 | G8: 760 | H8: Mobile Payment
A9: TXN_1498 | B9: 45784 | C9: Electric Accessories | D9: Elec_Earphones | E9: 350 | F9: 5 | G9: 1750 | H9: Cash
A10: TXN_1143 | B10: 45740 | C10: Furniture | D10: Furn_Lamp | E10: 700 | F10: 3 | G10: 2100 | H10: Credit Card
A11: TXN_1092 | B11: 45893 | C11: Beverages | D11: Bev_Tea_100g | E11: 90 | F11: 6 | G11: 540 | H11: Debit Card
A12: TXN_1540 | B12: 45734 | C12: Electric Accessories | D12: Elec_Cable_USB | E12: 150 | F12: 1 | G12: 150 | H12: Credit Card
A13: TXN_1574 | B13: 45894 | C13: Computers | D13: Comp_Webcam | E13: 1200 | F13: 5 | G13: 6000 | H13: Mobile Payment
A14: TXN_1014 | B14: 45897 | C14: Patisserie | D14: Pat_Donut | E14: 30 | F14: 6 | G14: 180 | H14: Cash
A15: TXN_1543 | B15: 45683 | C15: Butchers | D15: Meat_Fish_1kg | E15: 380 | G15: 380 | H15: Mobile Payment
A16: TXN_1086 | B16: 45855 | C16: Patisserie | D16: Pat_Donut | E16: 30 | F16: 1 | G16: 45 | H16: Debit Card
A17: TXN_1053 | B17: 45712 | C17: Computers | D17: Comp_Keyboard | E17: 800 | F17: 4 | G17: 3200 | H17: Mobile Payment
A18: TXN_1490 | B18: 45854 | C18: Electric Accessories | D18: Elec_Charger | E18: 400 | G18: 2000 | H18: Cash
A19: TXN_1207 | B19: 45792 | C19: Electric Accessories | E19: 90 | F19: 1 | G19: 90 | H19: Mobile Payment
A20: TXN_1554 | B20: 45799 | C20: Food | D20: Food_Rice_1kg | E20: 70 | F20: 3 | G20: 210 | H20: Cash
A21: TXN_1544 | B21: 45812 | C21: Beverages | D21: Bev_Tea_100g | E21: 90 | F21: 3 | G21: 270 | H21: Mobile Payment
A22: TXN_1397 | B22: 45806 | C22: Milk Products | D22: Milk_Cheese_200g | F22: 5 | G22: 550 | H22: Credit Card
A23: TXN_1372 | B23: 45694 | C23: Milk Products | E23: 110 | F23: 1 | G23: 110 | H23: Mobile Payment
A24: TXN_1224 | B24: 45870 | C24: Patisserie | D24: Pat_Cake_Slice | E24: 90 | F24: 1 | H24: Mobile Payment
A25: TXN_1101 | B25: 45681 | C25: Furniture | D25: Furn_Cushion | E25: 350 | F25: 3 | G25: 1050 | H25: Credit Card
A26: TXN_1049 | B26: 45721 | C26: Butchers | D26: Meat_Mutton_1kg | F26: 1 | G26: 650 | H26: Credit Card
A27: TXN_1528 | B27: 45685 | C27: Electric Accessories | D27: Elec_Earphones | E27: 350 | F27: 2 | G27: 700 | H27: Cash
A28: TXN_1166 | B28: 45856 | C28: Furniture | D28: Furn_Cushion | E28: 350 | F28: 2 | G28: 700 | H28: Mobile Payment
A29: TXN_1247 | B29: 45888 | C29: Butchers | E29: 75 | F29: 5 | G29: 375 | H29: Debit Card
A30: TXN_1114 | B30: 45678 | C30: Butchers | D30: Meat_Chicken_1kg | F30: 5 | G30: 1100 | H30: Credit Card
A31: TXN_1176 | B31: 45673 | C31: Food | D31: Food_Oats_1kg | E31: 120 | F31: 1 | G31: 120 | H31: Credit Card
A32: TXN_1056 | B32: 45672 | C32: Patisserie | D32: Pat_Cake_Slice | E32: 90 | F32: 2 | G32: 180 | H32: Cash
A33: TXN_1055 | B33: 45766 | C33: Electric Accessories | D33: Elec_Powerbank | F33: 3 | G33: 2700 | H33: Mobile Payment
A34: TXN_1400 | B34: 45824 | C34: Furniture | D34: Furn_Small_Table | E34: 3200 | F34: 3 | G34: 9600 | H34: Credit Card
A35: TXN_1398 | B35: 45888 | C35: Furniture | D35: Furn_Cushion | E35: 350 | F35: 6 | G35: 2100 | H35: Debit Card
A36: TXN_1323 | B36: 45745 | C36: Milk Products | D36: Milk_Butter_500g | F36: 2 | G36: 500 | H36: Mobile Payment
A37: TXN_1121 | B37: 45782 | C37: patisserie | D37: Pat_Donut | E37: 30 | F37: 4 | G37: 120 | H37: Cash
A38: TXN_1201 | B38: 45781 | C38: Electric Accessories | D38: Elec_Batteries_4pk | E38: 90 | F38: 5 | H38: Debit Card
A39: TXN_1091 | B39: 45791 | C39: Electric Accessories | D39: Elec_Earphones | E39: 350 | F39: 1 | G39: 525 | H39: Credit Card
A40: TXN_1364 | B40: 45835 | C40: Milk Products | D40: Milk_Butter_500g | E40: 250 | F40: 4 | G40: 1500 | H40: Mobile Payment
...

Sheet Reference Table
A1: Item | B1: Price Per Unit | C1: Category
A2: Milk_Cheese_200g | B2: 110 | C2: =IFERROR(INDEX('Raw Data'!C:C,MATCH(A2,'Raw Data'!D:D,0)),"") -> Milk Products
A3: Furn_Chair | B3: 2500 | C3: =IFERROR(INDEX('Raw Data'!C:C,MATCH(A3,'Raw Data'!D:D,0)),"") -> Furniture
A4: Milk_Butter_500g | B4: 250 | C4: =IFERROR(INDEX('Raw Data'!C:C,MATCH(A4,'Raw Data'!D:D,0)),"") -> Milk Products
A5: Meat_Chicken_1kg | B5: 220 | C5: =IFERROR(INDEX('Raw Data'!C:C,MATCH(A5,'Raw Data'!D:D,0)),"") -> Butchers
A6: Pat_Cake_Slice | B6: 90 | C6: =IFERROR(INDEX('Raw Data'!C:C,MATCH(A6,'Raw Data'!D:D,0)),"") -> Patisserie
A7: Elec_Earphones | B7: 350 | C7: =IFERROR(INDEX('Raw Data'!C:C,MATCH(A7,'Raw Data'!D:D,0)),"") -> Electric Accessories
A8: Furn_Lamp | B8: 700 | C8: =IFERROR(INDEX('Raw Data'!C:C,MATCH(A8,'Raw Data'!D:D,0)),"") -> Furniture
A9: Elec_Cable_USB | B9: 150 | C9: =IFERROR(INDEX('Raw Data'!C:C,MATCH(A9,'Raw Data'!D:D,0)),"") -> Electric Accessories
A10: Comp_Webcam | B10: 1200 | C10: =IFERROR(INDEX('Raw Data'!C:C,MATCH(A10,'Raw Data'!D:D,0)),"") -> Computers
A11: Pat_Donut | B11: 30 | C11: =IFERROR(INDEX('Raw Data'!C:C,MATCH(A11,'Raw Data'!D:D,0)),"") -> Patisserie
A12: Meat_Fish_1kg | B12: 380 | C12: =IFERROR(INDEX('Raw Data'!C:C,MATCH(A12,'Raw Data'!D:D,0)),"") -> Butchers
A13: Elec_Charger | B13: 400 | C13: =IFERROR(INDEX('Raw Data'!C:C,MATCH(A13,'Raw Data'!D:D,0)),"") -> Electric Accessories
... A32: Meat_Mutton_1kg | B32: 650 | C32: =IFERROR(INDEX('Raw Data'!C:C,MATCH(A32,'Raw Data'!D:D,0)),"") -> Butchers
A33: Bev_Tea_100g | B33: 90 | C33: Beverages
A34: Food_Pasta_500g | B34: 65 | C34: Food
A35: Food_Cereal_500g | B35: 150 | C35: Food
A36: Milk_Yogurt_400g | B36: 60 | C36: Milk Products
A37: Milk_Paneer_200g | B37: 80 | C37: Milk Products
A38: Milk_Ghee_500ml | B38: 350 | C38: Milk Products
A39: Pat_Cookie_Pack | B39: 55 | C39: Patisserie
A40: Meat_Mutton_1kg | B40: 650 | C40: Butchers
A41: Elec_Batteries_4pk | B41: 90 | C41: Electric Accessories
A42: Elec_Powerbank | B42: 900 | C42: Electric Accessories
A43: Comp_Mouse | B43: 500 | C43: Computers
A44: Comp_Keyboard | B44: 800 | C44: Computers
... A46: Furn_Cushion | B46: 350 | C46: Furniture

Sheet Cleaned Data
A1: Transaction ID | B1: Date | C1: Category | D1: Item | E1: Price Per Unit | F1: Quantity | G1: Total Spent | H1: Payment Method | I1: Item Fix Note | J1: Total Check
A2: ='Raw Data'!A2 -> TXN_1557 | B2: ='Raw Data'!B2 -> 45755 | C2: =IFERROR(INDEX('Reference Table'!$C$2:$C$46,MATCH(D2,'Reference Table'!$A$2:$A$46,0)),"Unknown") -> Milk Products | D2: {=IF(TRIM('Raw Data'!D2)<>"",TRIM('Raw Data'!D2),IFERROR(INDEX('Reference Table'!$A$2:$A$46,MATCH(VALUE('Raw Data'!E2),VALUE('Reference Table'!$B$2:$B$46),0)),"Unknown"))} -> Milk_Cheese_200g | E2: =IF('Raw Data'!E2<>"",'Raw Data'!E2,IFERROR(INDEX('Reference Table'!$B$2:$B$46,MATCH(D2,'Reference Table'!$A$2:$A$46,0)),"")) -> 110 | F2: =IF('Raw Data'!F2<>"",'Raw Data'!F2,IFERROR(ROUND('Raw Data'!G2/E2,0),"")) -> 6 | G2: =IF('Raw Data'!G2<>"",'Raw Data'!G2,IFERROR(ROUND(E2*F2,2),"")) -> 660 | H2: ='Raw Data'!H2 -> Credit Card | I2: =IF('Raw Data'!D2="",IF(D2="Unknown","Could not recover","Filled from Price lookup"),IF(TRIM('Raw Data'!D2)<>'Raw Data'!D2,"Trimmed whitespace","OK")) -> OK | J2: =IF(AND(E2<>"",F2<>"",G2<>""),IF(ROUND(E2*F2,2)=ROUND(G2,2),"OK","Mismatch"),"Incomplete") -> OK
A3: ='Raw Data'!A3 -> TXN_1251 | B3: ='Raw Data'!B3 -> 45808 | C3: =IFERROR(INDEX('Reference Table'!$C$2:$C$46,MATCH(D3,'Reference Table'!$A$2:$A$46,0)),"Unknown") -> Furniture | D3: {=IF(TRIM('Raw Data'!D3)<>"",TRIM('Raw Data'!D3),IFERROR(INDEX('Reference Table'!$A$2:$A$46,MATCH(VALUE('Raw Data'!E3),VALUE('Reference Table'!$B$2:$B$46),0)),"Unknown"))} -> Furn_Chair | E3: =IF('Raw Data'!E3<>"",'Raw Data'!E3,IFERROR(INDEX('Reference Table'!$B$2:$B$32,MATCH(D3,'Reference Table'!$A$2:$A$32,0)),"")) -> 2500 | F3: =IF('Raw Data'!F3<>"",'Raw Data'!F3,IFERROR(ROUND('Raw Data'!G3/E3,0),"")) -> 2 | G3: =IF('Raw Data'!G3<>"",'Raw Data'!G3,IFERROR(ROUND(E3*F3,2),"")) -> 5000 | H3: ='Raw Data'!H3 -> Credit Card | I3: =IF('Raw Data'!D3="",IF(D3="Unknown","Could not recover","Filled from Price lookup"),IF(TRIM('Raw Data'!D3)<>'Raw Data'!D3,"Trimmed whitespace","OK")) -> OK | J3: =IF(AND(E3<>"",F3<>"",G3<>""),IF(ROUND(E3*F3,2)=ROUND(G3,2),"OK","Mismatch"),"Incomplete") -> OK
A4: ='Raw Data'!A4 -> TXN_1150 | B4: ='Raw Data'!B4 -> 45860 | C4: =IFERROR(INDEX('Reference Table'!$C$2:$C$46,MATCH(D4,'Reference Table'!$A$2:$A$46,0)),"Unknown") -> Computers | D4: {=IF(TRIM('Raw Data'!D4)<>"",TRIM('Raw Data'!D4),IFERROR(INDEX('Reference Table'!$A$2:$A$46,MATCH(VALUE('Raw Data'!E4),VALUE('Reference Table'!$B$2:$B$46),0)),"Unknown"))} -> Comp_Keyboard | E4: =IF('Raw Data'!E4<>"",'Raw Data'!E4,IFERROR(INDEX('Reference Table'!$B$2:$B$32,MATCH(D4,'Reference Table'!$A$2:$A$32,0)),"")) -> 800 | F4: =IF('Raw Data'!F4<>"",'Raw Data'!F4,IFERROR(ROUND('Raw Data'!G4/E4,0),"")) -> 4 | G4: =IF('Raw Data'!G4<>"",'Raw Data'!G4,IFERROR(ROUND(E4*F4,2),"")) -> 3200 | H4: ='Raw Data'!H4 -> Cash | I4: =IF('Raw Data'!D4="",IF(D4="Unknown","Could not recover","Filled from Price lookup"),IF(TRIM('Raw Data'!D4)<>'Raw Data'!D4,"Trimmed whitespace","OK")) -> Filled from Price lookup | J4: =IF(AND(E4<>"",F4<>"",G4<>""),IF(ROUND(E4*F4,2)=ROUND(G4,2),"OK","Mismatch"),"Incomplete") -> OK
A5: ='Raw Data'!A5 -> TXN_1350 | B5: ='Raw Data'!B5 -> 45829 | C5: =IFERROR(INDEX('Reference Table'!$C$2:$C$46,MATCH(D5,'Reference Table'!$A$2:$A$46,0)),"Unknown") -> Milk Products | D5: {=IF(TRIM('Raw Data'!D5)<>"",TRIM('Raw Data'!D5),IFERROR(INDEX('Reference Table'!$A$2:$A$46,MATCH(VALUE('Raw Data'!E5),VALUE('Reference Table'!$B$2:$B$46),0)),"Unknown"))} -> Milk_Butter_500g | E5: =IF('Raw Data'!E5<>"",'Raw Data'!E5,IFERROR(INDEX('Reference Table'!$B$2:$B$32,MATCH(D5,'Reference Table'!$A$2:$A$32,0)),"")) -> 250 | F5: =IF('Raw Data'!F5<>"",'Raw Data'!F5,IFERROR(ROUND('Raw Data'!G5/E5,0),"")) -> 6 | G5: =IF('Raw Data'!G5<>"",'Raw Data'!G5,IFERROR(ROUND(E5*F5,2),"")) -> 1500 | H5: ='Raw Data'!H5 -> Cash | I5: =IF('Raw Data'!D5="",IF(D5="Unknown","Could not recover","Filled from Price lookup"),IF(TRIM('Raw Data'!D5)<>'Raw Data'!D5,"Trimmed whitespace","OK")) -> OK | J5: =IF(AND(E5<>"",F5<>"",G5<>""),IF(ROUND(E5*F5,2)=ROUND(G5,2),"OK","Mismatch"),"Incomplete") -> OK
A6: ='Raw Data'!A6 -> TXN_1406 | B6: ='Raw Data'!B6 -> 45878 | C6: =IFERROR(INDEX('Reference Table'!$C$2:$C$46,MATCH(D6,'Reference Table'!$A$2:$A$46,0)),"Unknown") -> Butchers | D6: {=IF(TRIM('Raw Data'!D6)<>"",TRIM('Raw Data'!D6),IFERROR(INDEX('Reference Table'!$A$2:$A$46,MATCH(VALUE('Raw Data'!E6),VALUE('Reference Table'!$B$2:$B$46),0)),"Unknown"))} -> Meat_Chicken_1kg | E6: =IF('Raw Data'!E6<>"",'Raw Data'!E6,IFERROR(INDEX('Reference Table'!$B$2:$B$32,MATCH(D6,'Reference Table'!$A$2:$A$32,0)),"")) -> 220 | F6: =IF('Raw Data'!F6<>"",'Raw Data'!F6,IFERROR(ROUND('Raw Data'!G6/E6,0),"")) -> 6 | G6: =IF('Raw Data'!G6<>"",'Raw Data'!G6,IFERROR(ROUND(E6*F6,2),"")) -> 1320 | H6: ='Raw Data'!H6 -> Debit Card | I6: =IF('Raw Data'!D6="",IF(D6="Unknown","Could not recover","Filled from Price lookup"),IF(TRIM('Raw Data'!D6)<>'Raw Data'!D6,"Trimmed whitespace","OK")) -> OK | J6: =IF(AND(E6<>"",F6<>"",G6<>""),IF(ROUND(E6*F6,2)=ROUND(G6,2),"OK","Mismatch"),"Incomplete") -> OK
A7: ='Raw Data'!A7 -> TXN_1494 | B7: ='Raw Data'!B7 -> 45866 | C7: =IFERROR(INDEX('Reference Table'!$C$2:$C$46,MATCH(D7,'Reference Table'!$A$2:$A$46,0)),"Unknown") -> Patisserie | D7: {=IF(TRIM('Raw Data'!D7)<>"",TRIM('Raw Data'!D7),IFERROR(INDEX('Reference Table'!$A$2:$A$46,MATCH(VALUE('Raw Data'!E7),VALUE('Reference Table'!$B$2:$B$46),0)),"Unknown"))} -> Pat_Cake_Slice | E7: =IF('Raw Data'!E7<>"",'Raw Data'!E7,IFERROR(INDEX('Reference Table'!$B$2:$B$32,MATCH(D7,'Reference Table'!$A$2:$A$32,0)),"")) -> 90 | F7: =IF('Raw Data'!F7<>"",'Raw Data'!F7,IFERROR(ROUND('Raw Data'!G7/E7,0),"")) -> 2 | G7: =IF('Raw Data'!G7<>"",'Raw Data'!G7,IFERROR(ROUND(E7*F7,2),"")) -> 180 | H7: ='Raw Data'!H7 -> Debit Card | I7: =IF('Raw Data'!D7="",IF(D7="Unknown","Could not recover","Filled from Price lookup"),IF(TRIM('Raw Data'!D7)<>'Raw Data'!D7,"Trimmed whitespace","OK")) -> OK | J7: =IF(AND(E7<>"",F7<>"",G7<>""),IF(ROUND(E7*F7,2)=ROUND(G7,2),"OK","Mismatch"),"Incomplete") -> OK
A8: ='Raw Data'!A8 -> TXN_1547 | B8: ='Raw Data'!B8 -> 45705 | C8: =IFERROR(INDEX('Reference Table'!$C$2:$C$46,MATCH(D8,'Reference Table'!$A$2:$A$46,0)),"Unknown") -> Butchers | D8: {=IF(TRIM('Raw Data'!D8)<>"",TRIM('Raw Data'!D8),IFERROR(INDEX('Reference Table'!$A$2:$A$46,MATCH(VALUE('Raw Data'!E8),VALUE('Reference Table'!$B$2:$B$46),0)),"Unknown"))} -> Meat_Bacon_250g | E8: =IF('Raw Data'!E8<>"",'Raw Data'!E8,IFERROR(INDEX('Reference Table'!$B$2:$B$32,MATCH(D8,'Reference Table'!$A$2:$A$32,0)),"")) -> 190 | F8: =IF('Raw Data'!F8<>"",'Raw Data'!F8,IFERROR(ROUND('Raw Data'!G8/E8,0),"")) -> 4 | G8: =IF('Raw Data'!G8<>"",'Raw Data'!G8,IFERROR(ROUND(E8*F8,2),"")) -> 760 | H8: ='Raw Data'!H8 -> Mobile Payment | I8: =IF('Raw Data'!D8="",IF(D8="Unknown","Could not recover","Filled from Price lookup"),IF(TRIM('Raw Data'!D8)<>'Raw Data'!D8,"Trimmed whitespace","OK")) -> Filled from Price lookup | J8: =IF(AND(E8<>"",F8<>"",G8<>""),IF(ROUND(E8*F8,2)=ROUND(G8,2),"OK","Mismatch"),"Incomplete") -> OK
A9: ='Raw Data'!A9 -> TXN_1498 | B9: ='Raw Data'!B9 -> 45784 | C9: =IFERROR(INDEX('Reference Table'!$C$2:$C$46,MATCH(D9,'Reference Table'!$A$2:$A$46,0)),"Unknown") -> Electric Accessories | D9: {=IF(TRIM('Raw Data'!D9)<>"",TRIM('Raw Data'!D9),IFERROR(INDEX('Reference Table'!$A$2:$A$46,MATCH(VALUE('Raw Data'!E9),VALUE('Reference Table'!$B$2:$B$46),0)),"Unknown"))} -> Elec_Earphones | E9: =IF('Raw Data'!E9<>"",'Raw Data'!E9,IFERROR(INDEX('Reference Table'!$B$2:$B$32,MATCH(D9,'Reference Table'!$A$2:$A$32,0)),"")) -> 350 | F9: =IF('Raw Data'!F9<>"",'Raw Data'!F9,IFERROR(ROUND('Raw Data'!G9/E9,0),"")) -> 5 | G9: =IF('Raw Data'!G9<>"",'Raw Data'!G9,IFERROR(ROUND(E9*F9,2),"")) -> 1750 | H9: ='Raw Data'!H9 -> Cash | I9: =IF('Raw Data'!D9="",IF(D9="Unknown","Could not recover","Filled from Price lookup"),IF(TRIM('Raw Data'!D9)<>'Raw Data'!D9,"Trimmed whitespace","OK")) -> OK | J9: =IF(AND(E9<>"",F9<>"",G9<>""),IF(ROUND(E9*F9,2)=ROUND(G9,2),"OK","Mismatch"),"Incomplete") -> OK
A10: ='Raw Data'!A10 -> TXN_1143 | B10: ='Raw Data'!B10 -> 45740 | C10: =IFERROR(INDEX('Reference Table'!$C$2:$C$46,MATCH(D10,'Reference Table'!$A$2:$A$46,0)),"Unknown") -> Furniture | D10: {=IF(TRIM('Raw Data'!D10)<>"",TRIM('Raw Data'!D10),IFERROR(INDEX('Reference Table'!$A$2:$A$46,MATCH(VALUE('Raw Data'!E10),VALUE('Reference Table'!$B$2:$B$46),0)),"Unknown"))} -> Furn_Lamp | E10: =IF('Raw Data'!E10<>"",'Raw Data'!E10,IFERROR(INDEX('Reference Table'!$B$2:$B$32,MATCH(D10,'Reference Table'!$A$2:$A$32,0)),"")) -> 700 | F10: =IF('Raw Data'!F10<>"",'Raw Data'!F10,IFERROR(ROUND('Raw Data'!G10/E10,0),"")) -> 3 | G10: =IF('Raw Data'!G10<>"",'Raw Data'!G10,IFERROR(ROUND(E10*F10,2),"")) -> 2100 | H10: ='Raw Data'!H10 -> Credit Card | I10: =IF('Raw Data'!D10="",IF(D10="Unknown","Could not recover","Filled from Price lookup"),IF(TRIM('Raw Data'!D10)<>'Raw Data'!D10,"Trimmed whitespace","OK")) -> OK | J10: =IF(AND(E10<>"",F10<>"",G10<>""),IF(ROUND(E10*F10,2)=ROUND(G10,2),"OK","Mismatch"),"Incomplete") -> OK
A11: ='Raw Data'!A11 -> TXN_1092 | B11: ='Raw Data'!B11 -> 45893 | C11: =IFERROR(INDEX('Reference Table'!$C$2:$C$46,MATCH(D11,'Reference Table'!$A$2:$A$46,0)),"Unknown") -> Beverages | D11: {=IF(TRIM('Raw Data'!D11)<>"",TRIM('Raw Data'!D11),IFERROR(INDEX('Reference Table'!$A$2:$A$46,MATCH(VALUE('Raw Data'!E11),VALUE('Reference Table'!$B$2:$B$46),0)),"Unknown"))} -> Bev_Tea_100g | E11: =IF('Raw Data'!E11<>"",'Raw Data'!E11,IFERROR(INDEX('Reference Table'!$B$2:$B$32,MATCH(D11,'Reference Table'!$A$2:$A$32,0)),"")) -> 90 | F11: =IF('Raw Data'!F11<>"",'Raw Data'!F11,IFERROR(ROUND('Raw Data'!G11/E11,0),"")) -> 6 | G11: =IF('Raw Data'!G11<>"",'Raw Data'!G11,IFERROR(ROUND(E11*F11,2),"")) -> 540 | H11: ='Raw Data'!H11 -> Debit Card | I11: =IF('Raw Data'!D11="",IF(D11="Unknown","Could not recover","Filled from Price lookup"),IF(TRIM('Raw Data'!D11)<>'Raw Data'!D11,"Trimmed whitespace","OK")) -> OK | J11: =IF(AND(E11<>"",F11<>"",G11<>""),IF(ROUND(E11*F11,2)=ROUND(G11,2),"OK","Mismatch"),"Incomplete") -> OK
A12: ='Raw Data'!A12 -> TXN_1540 | B12: ='Raw Data'!B12 -> 45734 | C12: =IFERROR(INDEX('Reference Table'!$C$2:$C$46,MATCH(D12,'Reference Table'!$A$2:$A$46,0)),"Unknown") -> Electric Accessories | D12: {=IF(TRIM('Raw Data'!D12)<>"",TRIM('Raw Data'!D12),IFERROR(INDEX('Reference Table'!$A$2:$A$46,MATCH(VALUE('Raw Data'!E12),VALUE('Reference Table'!$B$2:$B$46),0)),"Unknown"))} -> Elec_Cable_USB | E12: =IF('Raw Data'!E12<>"",'Raw Data'!E12,IFERROR(INDEX('Reference Table'!$B$2:$B$32,MATCH(D12,'Reference Table'!$A$2:$A$32,0)),"")) -> 150 | F12: =IF('Raw Data'!F12<>"",'Raw Data'!F12,IFERROR(ROUND('Raw Data'!G12/E12,0),"")) -> 1 | G12: =IF('Raw Data'!G12<>"",'Raw Data'!G12,IFERROR(ROUND(E12*F12,2),"")) -> 150 | H12: ='Raw Data'!H12 -> Credit Card | I12: =IF('Raw Data'!D12="",IF(D12="Unknown","Could not recover","Filled from Price lookup"),IF(TRIM('Raw Data'!D12)<>'Raw Data'!D12,"Trimmed whitespace","OK")) -> OK | J12: =IF(AND(E12<>"",F12<>"",G12<>""),IF(ROUND(E12*F12,2)=ROUND(G12,2),"OK","Mismatch"),"Incomplete") -> OK
A13: ='Raw Data'!A13 -> TXN_1574 | B13: ='Raw Data'!B13 -> 45894 | C13: =IFERROR(INDEX('Reference Table'!$C$2:$C$46,MATCH(D13,'Reference Table'!$A$2:$A$46,0)),"Unknown") -> Computers | D13: {=IF(TRIM('Raw Data'!D13)<>"",TRIM('Raw Data'!D13),IFERROR(INDEX('Reference Table'!$A$2:$A$46,MATCH(VALUE('Raw Data'!E13),VALUE('Reference Table'!$B$2:$B$46),0)),"Unknown"))} -> Comp_Webcam | E13: =IF('Raw Data'!E13<>"",'Raw Data'!E13,IFERROR(INDEX('Reference Table'!$B$2:$B$32,MATCH(D13,'Reference Table'!$A$2:$A$32,0)),"")) -> 1200 | F13: =IF('Raw Data'!F13<>"",'Raw Data'!F13,IFERROR(ROUND('Raw Data'!G13/E13,0),"")) -> 5 | G13: =IF('Raw Data'!G13<>"",'Raw Data'!G13,IFERROR(ROUND(E13*F13,2),"")) -> 6000 | H13: ='Raw Data'!H13 -> Mobile Payment | I13: =IF('Raw Data'!D13="",IF(D13="Unknown","Could not recover","Filled from Price lookup"),IF(TRIM('Raw Data'!D13)<>'Raw Data'!D13,"Trimmed whitespace","OK")) -> OK | J13: =IF(AND(E13<>"",F13<>"",G13<>""),IF(ROUND(E13*F13,2)=ROUND(G13,2),"OK","Mismatch"),"Incomplete") -> OK
A14: ='Raw Data'!A14 -> TXN_1014 | B14: ='Raw Data'!B14 -> 45897 | C14: =IFERROR(INDEX('Reference Table'!$C$2:$C$46,MATCH(D14,'Reference Table'!$A$2:$A$46,0)),"Unknown") -> Patisserie | D14: {=IF(TRIM('Raw Data'!D14)<>"",TRIM('Raw Data'!D14),IFERROR(INDEX('Reference Table'!$A$2:$A$46,MATCH(VALUE('Raw Data'!E14),VALUE('Reference Table'!$B$2:$B$46),0)),"Unknown"))} -> Pat_Donut | E14: =IF('Raw Data'!E14<>"",'Raw Data'!E14,IFERROR(INDEX('Reference Table'!$B$2:$B$32,MATCH(D14,'Reference Table'!$A$2:$A$32,0)),"")) -> 30 | F14: =IF('Raw Data'!F14<>"",'Raw Data'!F14,IFERROR(ROUND('Raw Data'!G14/E14,0),"")) -> 6 | G14: =IF('Raw Data'!G14<>"",'Raw Data'!G14,IFERROR(ROUND(E14*F14,2),"")) -> 180 | H14: ='Raw Data'!H14 -> Cash | I14: =IF('Raw Data'!D14="",IF(D14="Unknown","Could not recover","Filled from Price lookup"),IF(TRIM('Raw Data'!D14)<>'Raw Data'!D14,"Trimmed whitespace","OK")) -> OK | J14: =IF(AND(E14<>"",F14<>"",G14<>""),IF(ROUND(E14*F14,2)=ROUND(G14,2),"OK","Mismatch"),"Incomplete") -> OK
... A616: ='Raw Data'!A616 -> TXN_1191 | B616: ='Raw Data'!B616 -> 45726 | C616: =IFERROR(INDEX('Reference Table'!$C$2:$C$46,MATCH(D616,'Reference Table'!$A$2:$A$46,0)),"Unknown") -> Beverages | D616: {=IF(TRIM('Raw Data'!D616)<>"",TRIM('Raw Data'!D616),IFERROR(INDEX('Reference Table'!$A$2:$A$46,MATCH(VALUE('Raw Data'!E616),VALUE('Reference Table'!$B$2:$B$46),0)),"Unknown"))} -> Bev_Coffee_200g | E616: =IF('Raw Data'!E616<>"",'Raw Data'!E616,IFERROR(INDEX('Reference Table'!$B$2:$B$32,MATCH(D616,'Reference Table'!$A$2:$A$32,0)),"")) -> 180 | F616: =IF('Raw Data'!F616<>"",'Raw Data'!F616,IFERROR(ROUND('Raw Data'!G616/E616,0),"")) -> 2 | G616: =IF('Raw Data'!G616<>"",'Raw Data'!G616,IFERROR(ROUND(E616*F616,2),"")) -> 360 | H616: ='Raw Data'!H616 -> Credit Card | I616: =IF('Raw Data'!D616="",IF(D616="Unknown","Could not recover","Filled from Price lookup"),IF(TRIM('Raw Data'!D616)<>'Raw Data'!D616,"Trimmed whitespace","OK")) -> OK | J616: =IF(AND(E616<>"",F616<>"",G616<>""),IF(ROUND(E616*F616,2)=ROUND(G616,2),"OK","Mismatch"),"Incomplete") -> OK
